Workbook

Sheet 00 Indice
A1: Consolidado ICR - datos, calculos e indicadores
A2: Un solo libro con (1) el inventario de bases, (2) el catalogo de todos los calculos, y (3) una hoja por bloque de indicadores. Trazabilidad: las columnas VERDES contienen la FORMULA VIVA de Excel que recomputa el indicador desde sus insumos (con una columna 'dif' que debe dar ~0); las columnas NARANJAS son resultados de algebra matricial (inversas de Leontief/Ghosh) calculados en Python y validados contra INEGI a precision de maquina (~1e-15), con su script y CSV. Ninguna cifra es un numero suelto: o se recomputa aqui, o apunta a su script. Fecha de generacion: 2026-09-28.
A3: Hoja | B3: Contenido | C3: CSV fuente | D3: Script | E3: Tipo de trazabilidad
A4: 01 Bases de datos | B4: Inventario de todas las fuentes originales | C4: varias | D4: - | E4: Catalogo
A5: 02 Catalogo de calculos | B5: Todos los indicadores con formula, script y tipo de traza | C5: varias | D5: varios | E5: Catalogo
A6: 07 HHI numeradores | B6: Participaciones empresa/mina con fuente y pagina; share recomputado | C6: hhi_numeradores.csv | D6: hhi_2024.py / hhi_1994_2003.py | E6: Formula viva (share)
A7: 08 HHI serie | B7: HHI por mineral-anio con metodo/cobertura por fila | C7: hhi_consolidado.csv | D7: hhi_consolidado_2004_2020.py, hhi_2024.py, hhi_1994_2003.py | E7: Resultado + metodo por fila
A8: 09 CCV | B8: CCV por mineral-anio; numerador y denominador con recomputo | C8: ccv_serie.csv | D8: ccv_download.py, ccv_calc.py, ccv_fill_gaps.py | E8: Formula viva
A9: 10 Precios | B9: Precio anual de referencia por mineral con metodo de empalme | C9: precios_usgs_anual_empalmado.csv | D9: (extraccion USGS) | E9: Resultado + procedencia
A10: 11 Peso bloque prod | B10: Valor de produccion del bloque; V=Q*p y share recomputados | C10: peso_bloque_hist_produccion.csv | D10: peso_bloque_historico.py | E10: Formula viva
A11: 12 Peso bloque X | B11: % del bloque en exportaciones nacionales; recomputado | C11: peso_bloque_hist_exportaciones.csv | D11: peso_bloque_historico.py | E11: Formula viva
A12: 13 Peso bloque PIB | B12: PIB/VBP/empleo del bloque y participaciones; recomputado | C12: peso_bloque_mineria.csv | D12: peso_bloque.py | E12: Formula viva
A13: 14 MIP encadenam | B13: VBP, DI/VBP, Leontief/Ghosh y Rasmussen por mineral (2013/2018) | C13: mip_encadenamientos_minerales.csv | D13: mip_calc.py | E13: Resultado validado + Rasmussen formula viva
A14: 15 MIP eslabones | B14: Ghosh por eslabon (L1/L2/L3) por mineral | C14: mip_encadenamientos_eslabones.csv | D14: mip_eslabones.py | E14: Resultado validado
... A31: 24 HEM estatal | B31: HEM backward/forward/total de la mineria por entidad (2018) | C31: hem_estatal_mineria.csv | D31: hem_estatal.py | E31: Resultado validado + total formula viva

Sheet 01 Bases de datos
A1: Bases de datos utilizadas en la ICR
A2: Inventario de todas las fuentes que alimentan los calculos. Detalle por hoja en 10 Datos/Catalogo de Bases de Datos.md. Ademas de estas bases originales, todas las hojas estan exportadas a CSV limpio en 10 Datos/raw/csv/ (40 archivos).
A3: Bloque | B3: Fuente / archivo | C3: Contenido | D3: Periodo | E3: Utilidad | F3: Ubicacion en el repositorio
A4: 01 Criticidad | B4: USGS/Gobierno EE.UU. + Comision Europea (listas de criticidad) | C4: Clasificacion oficial de criticidad por mineral (riesgo de suministro, importancia economica) | D4: 2018-2023 | E4: Directa (criterio 1 del corpus) | F4: Bases Originales/01 Criticidad y Produccion Historica/1. minerales criticos.xlsx
A5: 01 Produccion hist. | B5: INEGI / SGM (hoja Produccion) | C5: Valor de produccion minera nacional, todos los minerales, MDP | D5: 1998-2024 | E5: Indirecta (contexto peso del bloque) | F5: idem, hoja 'Produccion'
A6: 02 Prod. y precios | B6: INEGI Banco de Indicadores | C6: Valor y volumen de produccion MENSUAL de los 10 minerales del corpus | D6: 2000-2025 | E6: Directa (valor de produccion, precio implicito) | F6: Bases Originales/02 Produccion y Precios Nacionales/2. produccion y precios.xlsx
A7: 03 Precios Cochilco | B7: Comision Chilena del Cobre (LME/COMEX) | C7: Precios internacionales mensuales, USD, 5 metales (Cu, Ag, Au, Pb, Zn) | D7: 1960-2024 | E7: Directa (validacion de precios) | F7: Bases Originales/03 Precios Internacionales Cochilco/ (5 archivos)
A8: 04 Comercio ext. | B8: CAMIMEX, Informe Anual (extraccion manual de PDF) | C8: Exportaciones/importaciones/balanza por producto, USD | D8: 2015-2024 | E8: Directa (CCV tramo reciente) | F8: Bases Originales/04 Comercio Exterior/4. balanza comercial.xlsx
A9: 05 Reservas mundo | B9: USGS / fuentes mundiales | C9: Produccion y reservas por pais y mineral, % mundial (una foto) | D9: corte unico | E9: Indirecta (posicion mundial de Mexico) | F9: Bases Originales/05 Reservas y Produccion Mundial/3. reservas y produccion mundial.xlsx
A10: 06 USGS DS-140 | B10: USGS Historical Statistics for Mineral and Material Commodities | C10: Valor unitario anual (USD/t nominal y constante 1998), desde 1900 | D10: 1900-2019 | E10: Directa (denominador CCV, precios de referencia) | F10: Bases Originales/06 USGS DS-140/ (10 archivos ds140-*.xlsx)
A11: 07 USGS MCS/MYB | B11: USGS Mineral Commodity Summaries + Minerals Yearbook Mexico | C11: Estructura de la industria (empresas, capacidades) y produccion nacional; base del HHI 1994-2003 | D11: 1994-2024 | E11: Directa (HHI regimen, estructura industria) | F11: Bases Originales/07 USGS MCS/ (incl. MYB Mexico 1994-2003)
A12: 08 CAMIMEX | B12: Camara Minera de Mexico, Informes Anuales | C12: Produccion por mina/empresa y total nacional; base del HHI 2004-2024 | D12: 2004-2025 | E12: Directa (numeradores HHI) | F12: Bases Originales/08 CAMIMEX Informes Anuales/
A13: 09 SGM Anuarios | B13: Servicio Geologico Mexicano, Anuario Estadistico de la Mineria | C13: Produccion por entidad federativa (georreferenciacion) y valor minero por estado | D13: 2019-2025 | E13: Directa (georref cuantitativa 2024) | F13: Bases Originales/09 SGM Anuarios/
A14: 10 MIP INEGI | B14: INEGI, Matriz Insumo-Producto simetrica producto x producto (clase SCIAN 6d) | C14: Coef. tecnicos (ctec=A) y directos+indirectos (cdi=inversa Leontief); base 2013 y 2018 + ref. 2008 | D14: 2008/2013/2018 | E14: Directa (Leontief, Ghosh, Rasmussen, demanda intermedia) | F14: Bases Originales/10 MIP INEGI/
... A19: 15 Marco instit. | B19: Normativa (Ley Minera, reforma 2023, etc.) | C19: Marco institucional del sector (contexto Cap. IV/VII) | D19: - | E19: Indirecta (contexto) | F19: Bases Originales/15 Marco Institucional/

Sheet 02 Catalogo de calculos
A1: Catalogo de calculos e indicadores
A2: Todos los calculos del proyecto, con su formula, insumos, script reproducible y el tipo de trazabilidad ofrecido en este libro. Base metodologica: 00 Proyecto/Metodologia y auditoria/Auditoria de indicadores.md. VERDE = columna con formula viva de Excel; NARANJA = columna de procedencia (resultado de script validado).
A3: Grupo | B3: Indicador / calculo | C3: Que mide | D3: Formula / matematica | E3: Insumos | F3: Script | G3: CSV fuente | H3: Hoja en este libro | I3: Tipo de traza
A4: 0 Insumos | B4: Precios USGS empalmados | C4: Precio anual de referencia del producto refinado, USD/t (nominal y const. 1998) | D4: Empalme de series USGS por factor de enlace en anios de traslape; deflactor a 1998 | E4: USGS DS-140 / MYB | F4: (extraccion USGS) | G4: precios_usgs_anual_empalmado.csv | H4: 10 Precios | I4: Resultado + procedencia
A5: 0 Insumos | B5: Peso del bloque - produccion | C5: Valor de produccion del bloque y descomposicion precio/volumen | D5: V = Q x p ; indices de volumen y de precio entre t0 y t1 | E5: volumen (USGS/CAMIMEX) x precio empalmado | F5: peso_bloque_historico.py | G5: peso_bloque_hist_produccion.csv | H5: 11 Peso bloque prod | I5: Formula viva
A6: 0 Insumos | B6: Peso del bloque - exportaciones | C6: % del bloque en las exportaciones totales de Mexico | D6: share = X_bloque / X_nacional | E6: Comtrade + Banco Mundial TX.VAL.MRCH.CD.WT | F6: peso_bloque_historico.py | G6: peso_bloque_hist_exportaciones.csv | H6: 12 Peso bloque X | I6: Formula viva
A7: 0 Insumos | B7: Peso del bloque - PIB / empleo | C7: Participacion del bloque en PIB y empleo | D7: pct = valor_bloque / total_nacional | E7: MIP 2013/2018 (B.1bP, P.1, PT) | F7: peso_bloque.py | G7: peso_bloque_mineria.csv | H7: 13 Peso bloque PIB | I7: Formula viva
A8: 1 HHI | B8: HHI de concentracion extractiva | C8: Concentracion de la produccion por mineral (estructura de mercado) | D8: HHI = sum_i (s_i)^2 , s_i en % (escala 0-10000) | E8: participaciones empresa/mina y total nacional | F8: hhi_2024.py, hhi_consolidado_2004_2020.py, hhi_1994_2003.py | G8: hhi_numeradores.csv, hhi_consolidado.csv | H8: 07-08 HHI | I8: Formula viva (participaciones) + resultado (residual/regimen)
A9: 1 HHI | B9: HHI geografico | C9: Concentracion territorial de la extraccion entre entidades | D9: HHI_geo = sum_estado (s_estado)^2 | E9: produccion por estado 2024 (SGM) | F9: georref_regionalizacion.py | G9: georref_regionalizacion.csv | H9: 17 Georref | I9: Formula viva
A10: 2 MIP nacional | B10: Leontief (hacia atras) | C10: Traccion a proveedores de cada mineral | D10: a_ij=z_ij/x_j ; L=(I-A)^-1 ; hacia atras = suma de columna | E10: MIP INEGI 2013/2018 (ctec/cdi) | F10: mip_calc.py | G10: mip_encadenamientos_minerales.csv | H10: 14 MIP encadenam. | I10: Resultado validado (1e-15) + Rasmussen formula viva
A11: 2 MIP nacional | B11: Ghosh (hacia adelante) - central | C11: Distribucion de la produccion; si alimenta industria domestica | D11: b_ij=z_ij/x_i ; G=(I-B)^-1 ; hacia adelante = suma de fila | E11: MIP INEGI 2013/2018 | F11: mip_calc.py | G11: mip_encadenamientos_minerales.csv | H11: 14 MIP encadenam. | I11: Resultado validado + Rasmussen formula viva
A12: 2 MIP nacional | B12: Hirschman-Rasmussen | C12: Encadenamientos comparables entre ramas (media=1) | D12: suma sectorial / promedio de todas las sumas | E12: sumas de fila/columna de L y G | F12: mip_calc.py | G12: mip_encadenamientos_minerales.csv | H12: 14 MIP encadenam. | I12: Formula viva (normalizacion)
A13: 2 MIP nacional | B13: Demanda intermedia (DI/VBP) | C13: Fraccion a uso intermedio interno y sectores compradores | D13: DI/VBP ; share de la fila del mineral | E13: MIP INEGI | F13: mip_calc.py | G13: mip_demanda_intermedia_minerales.csv | H13: 16 Demanda interm. | I13: Formula viva
A14: 2 MIP nacional | B14: Encadenamiento por eslabon | C14: Si el arrastre se sostiene al descender L1->L2->L3 | D14: Ghosh-Rasmussen por clase SCIAN 331... por mineral | E14: MIP INEGI | F14: mip_eslabones.py | G14: mip_encadenamientos_eslabones.csv | H14: 15 MIP eslabones | I14: Resultado + Rasmussen formula viva
... A30: 8 Criticidad | B30: Criticidad por producto | C30: Eslabon de mayor criticidad de cada mineral y si Mexico lo produce/exporta/importa | D30: (clasificacion oficial USGS/UE/IEA) | E30: listas oficiales | F30: (fichado) | G30: criticidad_productos.csv | H30: 22 Criticidad | I30: Clasificacion

Sheet 07 HHI numeradores
A1: HHI - numeradores (participaciones por empresa/mina)
A2: Insumo del HHI: participacion de cada empresa/mina y total nacional, con FUENTE y PAGINA (CAMIMEX/USGS). La columna verde recomputa participacion = volumen / total_nacional x 100 SOLO cuando volumen y total estan en la MISMA unidad; una 'dif' grande marca filas donde la fuente narrativa mezcla unidades (p.ej. oro en 'miles oz' vs total en toneladas) o usa CAPACIDAD, no produccion (barita/fluorita duopolio => >100%). Por eso el HHI final por mineral-anio se arma con residual/'metodo' por fila en '08 HHI serie', no por division directa.
A3: mineral | B3: anio_dato | C3: nivel | D3: unidad_minera | E3: empresa | F3: estado | G3: volumen | H3: unidad_volumen | I3: participacion_pct | J3: total_nacional | K3: unidad_total | L3: fuente | M3: pagina | N3: nota | O3: participacion (=formula) % | P3: dif vs reportada
A4: Barita | B4: 2020 | C4: empresa | E4: Baramin | G4: 235000 | H4: toneladas | I4: 63.1 | J4: 372262 | K4: toneladas | L4: Informe CAMIMEX 2021 | N4: Baramin 235 mil t de 372262 = 63.1pct | O4: =IF(AND(ISNUMBER(G4),ISNUMBER(J4),J4<>0,H4=K4),G4/J4*100,"") | P4: =IF(AND(ISNUMBER(O4),ISNUMBER(I4)),ROUND(O4-I4,2),"")
A5: Barita | B5: 2021 | C5: empresa | E5: Baramin | G5: 264000 | H5: toneladas | I5: 82.3 | J5: 320642 | K5: toneladas | L5: Informe CAMIMEX 2022 p76 | N5: OJO: denominador barita | O5: =IF(AND(ISNUMBER(G5),ISNUMBER(J5),J5<>0,H5=K5),G5/J5*100,"") | P5: =IF(AND(ISNUMBER(O5),ISNUMBER(I5)),ROUND(O5-I5,2),"")
A6: Barita | B6: 2022 | C6: empresa | E6: Baramin | G6: 152000 | H6: toneladas | I6: 49.8 | J6: 305270 | K6: toneladas | L6: Informe CAMIMEX 2023 p74 | N6: Baramin 152k de 305k nacional (CAMIMEX) | O6: =IF(AND(ISNUMBER(G6),ISNUMBER(J6),J6<>0,H6=K6),G6/J6*100,"") | P6: =IF(AND(ISNUMBER(O6),ISNUMBER(I6)),ROUND(O6-I6,2),"")
A7: Barita | B7: 2023 | C7: empresa | E7: Baramin | G7: 109953 | H7: toneladas | I7: 37.1 | J7: 295989 | K7: toneladas | L7: Informe CAMIMEX 2024 p87 | N7: Baramin 109953 de 295989 nacional | O7: =IF(AND(ISNUMBER(G7),ISNUMBER(J7),J7<>0,H7=K7),G7/J7*100,"") | P7: =IF(AND(ISNUMBER(O7),ISNUMBER(I7)),ROUND(O7-I7,2),"")
A8: Barita | B8: 2024 | C8: empresa | E8: Baramin | G8: 59980 | H8: toneladas | I8: 24.6 | J8: 244269 | K8: toneladas | L8: Informe CAMIMEX 2025 p72 | N8: Baramin 59980 de 244269; agotamiento mina Grecia | O8: =IF(AND(ISNUMBER(G8),ISNUMBER(J8),J8<>0,H8=K8),G8/J8*100,"") | P8: =IF(AND(ISNUMBER(O8),ISNUMBER(I8)),ROUND(O8-I8,2),"")
A9: Cobre | B9: 2021 | C9: empresa | E9: Grupo Mexico | H9: 559833 | I9: 76.3 | J9: 734137 | K9: toneladas | L9: Informe CAMIMEX 2022 | M9: 44 | N9: Narrativa: 559833 t = 76.3%; siguen Frisco Santa Maria de la Paz Capstone Aura | O9: =IF(AND(ISNUMBER(G9),ISNUMBER(J9),J9<>0,H9=K9),G9/J9*100,"") | P9: =IF(AND(ISNUMBER(O9),ISNUMBER(I9)),ROUND(O9-I9,2),"")
A10: Cobre | B10: 2021 | C10: mina | D10: Aranzazu | E10: Aura Minerals | F10: Zac. | G10: 14700 | H10: toneladas | J10: 734137 | K10: toneladas | L10: Informe CAMIMEX 2022 | M10: 44 | N10: 14.70 miles t | O10: =IF(AND(ISNUMBER(G10),ISNUMBER(J10),J10<>0,H10=K10),G10/J10*100,"") | P10: =IF(AND(ISNUMBER(O10),ISNUMBER(I10)),ROUND(O10-I10,2),"")
A11: Cobre | B11: 2021 | C11: mina | D11: Bolivar | E11: Sierra Metals | F11: Chih. | G11: 7670 | H11: toneladas | J11: 734137 | K11: toneladas | L11: Informe CAMIMEX 2022 | M11: 44 | N11: 7.67 miles t | O11: =IF(AND(ISNUMBER(G11),ISNUMBER(J11),J11<>0,H11=K11),G11/J11*100,"") | P11: =IF(AND(ISNUMBER(O11),ISNUMBER(I11)),ROUND(O11-I11,2),"")
A12: Cobre | B12: 2021 | C12: mina | D12: Buenavista del Cobre | E12: Grupo Mexico | F12: Son. | G12: 341200 | H12: toneladas | J12: 734137 | K12: toneladas | L12: Informe CAMIMEX 2022 | M12: 44 | N12: Tabla top-15 en miles de t verificada en imagen (341.20) | O12: =IF(AND(ISNUMBER(G12),ISNUMBER(J12),J12<>0,H12=K12),G12/J12*100,"") | P12: =IF(AND(ISNUMBER(O12),ISNUMBER(I12)),ROUND(O12-I12,2),"")
A13: Cobre | B13: 2021 | C13: mina | D13: Capela | E13: Industrias Penoles | F13: Gro. | G13: 3210 | H13: toneladas | J13: 734137 | K13: toneladas | L13: Informe CAMIMEX 2022 | M13: 44 | N13: 3.21 miles t | O13: =IF(AND(ISNUMBER(G13),ISNUMBER(J13),J13<>0,H13=K13),G13/J13*100,"") | P13: =IF(AND(ISNUMBER(O13),ISNUMBER(I13)),ROUND(O13-I13,2),"")
A14: Cobre | B14: 2021 | C14: mina | D14: Charcas | E14: Grupo Mexico | F14: S.L.P. | G14: 3340 | H14: toneladas | J14: 734137 | K14: toneladas | L14: Informe CAMIMEX 2022 | M14: 44 | N14: 3.34 miles t | O14: =IF(AND(ISNUMBER(G14),ISNUMBER(J14),J14<>0,H14=K14),G14/J14*100,"") | P14: =IF(AND(ISNUMBER(O14),ISNUMBER(I14)),ROUND(O14-I14,2),"")
A15: Cobre | B15: 2021 | C15: mina | D15: Cozamin | E15: Capstone Mining | F15: Zac. | G15: 24420 | H15: toneladas | J15: 734137 | K15: toneladas | L15: Informe CAMIMEX 2022 | M15: 44 | N15: 24.42 miles t | O15: =IF(AND(ISNUMBER(G15),ISNUMBER(J15),J15<>0,H15=K15),G15/J15*100,"") | P15: =IF(AND(ISNUMBER(O15),ISNUMBER(I15)),ROUND(O15-I15,2),"")
A16: Cobre | B16: 2021 | C16: mina | D16: La Caridad | E16: Grupo Mexico | F16: Son. | G16: 102690 | H16: toneladas | J16: 734137 | K16: toneladas | L16: Informe CAMIMEX 2022 | M16: 44 | N16: 102.69 miles t | O16: =IF(AND(ISNUMBER(G16),ISNUMBER(J16),J16<>0,H16=K16),G16/J16*100,"") | P16: =IF(AND(ISNUMBER(O16),ISNUMBER(I16)),ROUND(O16-I16,2),"")
A17: Cobre | B17: 2021 | C17: mina | D17: La Paz | E17: Neg. Mra. Sta. Ma. de La Paz y Anexas | F17: S.L.P. | G17: 25210 | H17: toneladas | J17: 734137 | K17: toneladas | L17: Informe CAMIMEX 2022 | M17: 44 | N17: 25.21 miles t | O17: =IF(AND(ISNUMBER(G17),ISNUMBER(J17),J17<>0,H17=K17),G17/J17*100,"") | P17: =IF(AND(ISNUMBER(O17),ISNUMBER(I17)),ROUND(O17-I17,2),"")
A18: Cobre | B18: 2021 | C18: mina | D18: Sabinas | E18: Industrias Penoles | F18: Zac. | G18: 3680 | H18: toneladas | J18: 734137 | K18: toneladas | L18: Informe CAMIMEX 2022 | M18: 44 | N18: 3.68 miles t | O18: =IF(AND(ISNUMBER(G18),ISNUMBER(J18),J18<>0,H18=K18),G18/J18*100,"") | P18: =IF(AND(ISNUMBER(O18),ISNUMBER(I18)),ROUND(O18-I18,2),"")
A19: Cobre | B19: 2021 | C19: mina | D19: San Martin | E19: Grupo Mexico | F19: Zac. | G19: 3080 | H19: toneladas | J19: 734137 | K19: toneladas | L19: Informe CAMIMEX 2022 | M19: 44 | N19: 3.08 miles t | O19: =IF(AND(ISNUMBER(G19),ISNUMBER(J19),J19<>0,H19=K19),G19/J19*100,"") | P19: =IF(AND(ISNUMBER(O19),ISNUMBER(I19)),ROUND(O19-I19,2),"")
A20: Cobre | B20: 2021 | C20: mina | D20: Santa Barbara | E20: Grupo Mexico | F20: Chih. | G20: 2290 | H20: toneladas | J20: 734137 | K20: toneladas | L20: Informe CAMIMEX 2022 | M20: 44 | N20: 2.29 miles t | O20: =IF(AND(ISNUMBER(G20),ISNUMBER(J20),J20<>0,H20=K20),G20/J20*100,"") | P20: =IF(AND(ISNUMBER(O20),ISNUMBER(I20)),ROUND(O20-I20,2),"")
A21: Cobre | B21: 2021 | C21: mina | D21: Tayahua | E21: Minera Frisco | F21: Zac. | G21: 23230 | H21: toneladas | J21: 734137 | K21: toneladas | L21: Informe CAMIMEX 2022 | M21: 44 | N21: 23.23 miles t | O21: =IF(AND(ISNUMBER(G21),ISNUMBER(J21),J21<>0,H21=K21),G21/J21*100,"") | P21: =IF(AND(ISNUMBER(O21),ISNUMBER(I21)),ROUND(O21-I21,2),"")
... A24: Cobre | B24: 2021 | C24: mina | D24: Zimapan | E24: Santacruz Silver | F24: Hgo. | G24: 1820 | H24: toneladas | J24: 734137 | K24: toneladas | L24: Informe CAMIMEX 2022 | M24: 44 | N24: 1.82 miles t | O24: =IF(AND(ISNUMBER(G24),ISNUMBER(J24),J24<>0,H24=K24),G24/J24*100,"") | P24: =IF(AND(ISNUMBER(O24),ISNUMBER(I24)),ROUND(O24-I24,2),"")
A25: Cobre | B25: 2022 | C25: empresa | E25: Grupo Mexico | I25: 73.3 | J25: 753885 | K25: toneladas | L25: Informe CAMIMEX 2023 | M25: 49 | N25: Narrativa: mayor productor 73.3%; siguen Frisco Santa Maria de la Paz Capstone Invecture | O25: =IF(AND(ISNUMBER(G25),ISNUMBER(J25),J25<>0,H25=K25),G25/J25*100,"") | P25: =IF(AND(ISNUMBER(O25),ISNUMBER(I25)),ROUND(O25-I25,2),"")
A26: Cobre | B26: 2022 | C26: mina | D26: Aranzazu Holding | E26: Aura | F26: Zac. | G26: 16241 | H26: toneladas | J26: 753885 | K26: toneladas | L26: Informe CAMIMEX 2023 | M26: 49 | O26: =IF(AND(ISNUMBER(G26),ISNUMBER(J26),J26<>0,H26=K26),G26/J26*100,"") | P26: =IF(AND(ISNUMBER(O26),ISNUMBER(I26)),ROUND(O26-I26,2),"")
A27: Cobre | B27: 2022 | C27: mina | D27: Avino | E27: Avino Silver and Gold | F27: Dgo. | G27: 2950 | H27: toneladas | J27: 753885 | K27: toneladas | L27: Informe CAMIMEX 2023 | M27: 49 | O27: =IF(AND(ISNUMBER(G27),ISNUMBER(J27),J27<>0,H27=K27),G27/J27*100,"") | P27: =IF(AND(ISNUMBER(O27),ISNUMBER(I27)),ROUND(O27-I27,2),"")
A28: Cobre | B28: 2022 | C28: mina | D28: Bolivar | E28: Sierra Metals | F28: Chih. | G28: 5709 | H28: toneladas | J28: 753885 | K28: toneladas | L28: Informe CAMIMEX 2023 | M28: 49 | O28: =IF(AND(ISNUMBER(G28),ISNUMBER(J28),J28<>0,H28=K28),G28/J28*100,"") | P28: =IF(AND(ISNUMBER(O28),ISNUMBER(I28)),ROUND(O28-I28,2),"")
A29: Cobre | B29: 2022 | C29: mina | D29: Buenavista del Cobre | E29: Grupo Mexico | F29: Son. | G29: 338633 | H29: toneladas | J29: 753885 | K29: toneladas | L29: Informe CAMIMEX 2023 | M29: 49 | N29: Tabla top-15 verificada en imagen | O29: =IF(AND(ISNUMBER(G29),ISNUMBER(J29),J29<>0,H29=K29),G29/J29*100,"") | P29: =IF(AND(ISNUMBER(O29),ISNUMBER(I29)),ROUND(O29-I29,2),"")
A30: Cobre | B30: 2022 | C30: mina | D30: Campo Morado | E30: Luca Mining | F30: Gro. | G30: 11158 | H30: toneladas | J30: 753885 | K30: toneladas | L30: Informe CAMIMEX 2023 | M30: 49 | O30: =IF(AND(ISNUMBER(G30),ISNUMBER(J30),J30<>0,H30=K30),G30/J30*100,"") | P30: =IF(AND(ISNUMBER(O30),ISNUMBER(I30)),ROUND(O30-I30,2),"")
A31: Cobre | B31: 2022 | C31: mina | D31: Capela | E31: Industrias Penoles | F31: Gro. | G31: 3377 | H31: toneladas | J31: 753885 | K31: toneladas | L31: Informe CAMIMEX 2023 | M31: 49 | O31: =IF(AND(ISNUMBER(G31),ISNUMBER(J31),J31<>0,H31=K31),G31/J31*100,"") | P31: =IF(AND(ISNUMBER(O31),ISNUMBER(I31)),ROUND(O31-I31,2),"")
A32: Cobre | B32: 2022 | C32: mina | D32: Charcas | E32: Grupo Mexico | F32: S.L.P. | G32: 3257 | H32: toneladas | J32: 753885 | K32: toneladas | L32: Informe CAMIMEX 2023 | M32: 49 | O32: =IF(AND(ISNUMBER(G32),ISNUMBER(J32),J32<>0,H32=K32),G32/J32*100,"") | P32: =IF(AND(ISNUMBER(O32),ISNUMBER(I32)),ROUND(O32-I32,2),"")
A33: Cobre | B33: 2022 | C33: mina | D33: Cozamin | E33: Capstone Copper | F33: Zac. | G33: 24451 | H33: toneladas | J33: 753885 | K33: toneladas | L33: Informe CAMIMEX 2023 | M33: 49 | O33: =IF(AND(ISNUMBER(G33),ISNUMBER(J33),J33<>0,H33=K33),G33/J33*100,"") | P33: =IF(AND(ISNUMBER(O33),ISNUMBER(I33)),ROUND(O33-I33,2),"")
A34: Cobre | B34: 2022 | C34: mina | D34: La Caridad | E34: Grupo Mexico | F34: Son. | G34: 88492 | H34: toneladas | J34: 753885 | K34: toneladas | L34: Informe CAMIMEX 2023 | M34: 49 | O34: =IF(AND(ISNUMBER(G34),ISNUMBER(J34),J34<>0,H34=K34),G34/J34*100,"") | P34: =IF(AND(ISNUMBER(O34),ISNUMBER(I34)),ROUND(O34-I34,2),"")
A35: Cobre | B35: 2022 | C35: mina | D35: La Paz | E35: Nemisa | F35: S.L.P. | G35: 26016 | H35: toneladas | J35: 753885 | K35: toneladas | L35: Informe CAMIMEX 2023 | M35: 49 | O35: =IF(AND(ISNUMBER(G35),ISNUMBER(J35),J35<>0,H35=K35),G35/J35*100,"") | P35: =IF(AND(ISNUMBER(O35),ISNUMBER(I35)),ROUND(O35-I35,2),"")
A36: Cobre | B36: 2022 | C36: mina | D36: Piedras Verdes | E36: Invecture Group | F36: Son. | G36: 5446 | H36: toneladas | J36: 753885 | K36: toneladas | L36: Informe CAMIMEX 2023 | M36: 49 | O36: =IF(AND(ISNUMBER(G36),ISNUMBER(J36),J36<>0,H36=K36),G36/J36*100,"") | P36: =IF(AND(ISNUMBER(O36),ISNUMBER(I36)),ROUND(O36-I36,2),"")
A37: Cobre | B37: 2022 | C37: mina | D37: Sabinas | E37: Industrias Penoles | F37: Zac. | G37: 2771 | H37: toneladas | J37: 753885 | K37: toneladas | L37: Informe CAMIMEX 2023 | M37: 49 | O37: =IF(AND(ISNUMBER(G37),ISNUMBER(J37),J37<>0,H37=K37),G37/J37*100,"") | P37: =IF(AND(ISNUMBER(O37),ISNUMBER(I37)),ROUND(O37-I37,2),"")
A38: Cobre | B38: 2022 | C38: mina | D38: San Martin | E38: Grupo Mexico | F38: Zac. | G38: 3810 | H38: toneladas | J38: 753885 | K38: toneladas | L38: Informe CAMIMEX 2023 | M38: 49 | O38: =IF(AND(ISNUMBER(G38),ISNUMBER(J38),J38<>0,H38=K38),G38/J38*100,"") | P38: =IF(AND(ISNUMBER(O38),ISNUMBER(I38)),ROUND(O38-I38,2),"")
A39: Cobre | B39: 2022 | C39: mina | D39: Tayahua | E39: Minera Frisco | F39: Zac. | G39: 27331 | H39: toneladas | J39: 753885 | K39: toneladas | L39: Informe CAMIMEX 2023 | M39: 49 | O39: =IF(AND(ISNUMBER(G39),ISNUMBER(J39),J39<>0,H39=K39),G39/J39*100,"") | P39: =IF(AND(ISNUMBER(O39),ISNUMBER(I39)),ROUND(O39-I39,2),"")
A40: Cobre | B40: 2022 | C40: mina | D40: Velardena | E40: Industrias Penoles | F40: Dgo. | G40: 2400 | H40: toneladas | J40: 753885 | K40: toneladas | L40: Informe CAMIMEX 2023 | M40: 49 | N40: Top-15 suma 562042 | O40: =IF(AND(ISNUMBER(G40),ISNUMBER(J40),J40<>0,H40=K40),G40/J40*100,"") | P40: =IF(AND(ISNUMBER(O40),ISNUMBER(I40)),ROUND(O40-I40,2),"")
A41: Cobre | B41: 2023 | C41: empresa | E41: Grupo Mexico | I41: 76.8 | J41: 699118 | K41: toneladas | L41: Informe CAMIMEX 2024 | M41: 57 | N41: Narrativa: mayor productor 76.8%; siguen Nemisa Invecture Capstone Penoles | O41: =IF(AND(ISNUMBER(G41),ISNUMBER(J41),J41<>0,H41=K41),G41/J41*100,"") | P41: =IF(AND(ISNUMBER(O41),ISNUMBER(I41)),ROUND(O41-I41,2),"")
A42: Cobre | B42: 2023 | C42: mina | D42: Aranzazu | E42: Aura Minerals | F42: Zac. | G42: 16507 | H42: toneladas | J42: 699118 | K42: toneladas | L42: Informe CAMIMEX 2024 | M42: 57 | O42: =IF(AND(ISNUMBER(G42),ISNUMBER(J42),J42<>0,H42=K42),G42/J42*100,"") | P42: =IF(AND(ISNUMBER(O42),ISNUMBER(I42)),ROUND(O42-I42,2),"")
...

Sheet 08 HHI serie
A1: HHI - serie consolidada por mineral-anio (1994-2024)
A2: HHI = suma de cuotas al cuadrado (0-10000). Cada fila trae su 'metodo' y 'cobertura_pct': 2021-2024 por mina (comparable); 2004-2020 por regimen (cota inferior); 1994-2003 reconstruido de USGS MYB. Los niveles 1994-2020 se leen por TRAYECTORIA, no por nivel exacto. Resultado del script (incluye residual atomistico).
A3: mineral | B3: anio | C3: hhi | D3: cobertura_pct | E3: lider | F3: metodo | G3: nota
A4: cobre | B4: 1997 | C4: 6241 | D4: 79 | E4: Grupo Mexico ~79% | F4: lider-grupo Grupo Mexico (narrativa USGS) | G4: USGS MYB Mexico 1994-2003, Tabla 2 + narrativa: La Caridad+Cananea 79% del cobre mina nacional; cota inferior; nivel grupo (no comparable con 2004+)
A5: cobre | B5: 1998 | C5: 6724 | D5: 82 | E5: Grupo Mexico ~82% | F5: lider-grupo Grupo Mexico (narrativa USGS) | G5: USGS MYB Mexico 1994-2003, Tabla 2 + narrativa: La Caridad+Cananea 82% del cobre mina nacional; cota inferior; nivel grupo (no comparable con 2004+)
A6: cobre | B6: 2000 | C6: 6400 | D6: 80 | E6: Grupo Mexico ~80% | F6: lider-grupo Grupo Mexico (narrativa USGS) | G6: USGS MYB Mexico 1994-2003, Tabla 2 + narrativa: La Caridad+Cananea 80% del cobre mina nacional; cota inferior; nivel grupo (no comparable con 2004+)
A7: cobre | B7: 2001 | C7: 7225 | D7: 85 | E7: Grupo Mexico ~85% | F7: lider-grupo Grupo Mexico (narrativa USGS) | G7: USGS MYB Mexico 1994-2003, Tabla 2 + narrativa: La Caridad+Cananea 85% del cobre mina nacional; cota inferior; nivel grupo (no comparable con 2004+)
A8: cobre | B8: 2002 | C8: 6889 | D8: 83 | E8: Grupo Mexico ~83% | F8: lider-grupo Grupo Mexico (narrativa USGS) | G8: USGS MYB Mexico 1994-2003, Tabla 2 + narrativa: La Caridad+Cananea 83% del cobre mina nacional; cota inferior; nivel grupo (no comparable con 2004+)
A9: cobre | B9: 2003 | C9: 6400 | D9: 80 | E9: Grupo Mexico ~80% | F9: lider-grupo Grupo Mexico (narrativa USGS) | G9: USGS MYB Mexico 1994-2003, Tabla 2 + narrativa: La Caridad+Cananea 80% del cobre mina nacional; cota inferior; nivel grupo (no comparable con 2004+)
A10: cobre | B10: 2005 | C10: 7500 | D10: 87 | E10: Grupo Mexico 86.6% | F10: lider/grupos conocidos + residual atomistico (aprox.) | G10: cota inferior: solo participaciones documentadas; residual tratado como atomistico
A11: cobre | B11: 2006 | C11: 6806 | D11: 82 | E11: Grupo Mexico 82.5% | F11: lider/grupos conocidos + residual atomistico (aprox.) | G11: cota inferior: solo participaciones documentadas; residual tratado como atomistico
A12: cobre | B12: 2008 | C12: 2570 | D12: 51 | E12: Grupo Mexico 50.7% | F12: lider/grupos conocidos + residual atomistico (aprox.) | G12: cota inferior: solo participaciones documentadas; residual tratado como atomistico
A13: cobre | B13: 2010 | C13: 2621 | D13: 51 | E13: Grupo Mexico 51.2% | F13: lider/grupos conocidos + residual atomistico (aprox.) | G13: cota inferior: solo participaciones documentadas; residual tratado como atomistico
A14: cobre | B14: 2011 | C14: 4356 | D14: 66 | E14: Grupo Mexico 66.0% | F14: lider/grupos conocidos + residual atomistico (aprox.) | G14: cota inferior: solo participaciones documentadas; residual tratado como atomistico
A15: cobre | B15: 2013 | C15: 4147 | D15: 64 | E15: Grupo Mexico 64.4% | F15: lider/grupos conocidos + residual atomistico (aprox.) | G15: cota inferior: solo participaciones documentadas; residual tratado como atomistico
... A18: cobre | B18: 2020 | C18: 6209 | D18: 79 | E18: Grupo Mexico 78.8% | F18: lider/grupos conocidos + residual atomistico (aprox.) | G18: cota inferior: solo participaciones documentadas; residual tratado como atomistico
A19: cobre | B19: 2021 | C19: 3841 | D19: 76 | E19: Grupo Mexico 62% | F19: mina->grupo vs total nacional
A20: cobre | B20: 2022 | C20: 3362 | D20: 75 | E20: Grupo Mexico 58% | F20: mina->grupo vs total nacional
A21: cobre | B21: 2023 | C21: 3764 | D21: 77 | E21: Grupo Mexico 61% | F21: mina->grupo vs total nacional
A22: cobre | B22: 2024 | C22: 3557 | D22: 74 | E22: Grupo Mexico 59% | F22: mina->grupo vs total nacional (total cobre estimado) | G22: detalle por mina 2024 (CAMIMEX/SGM); total nacional 2024 estimado ~755,000 t (grafico SGM)
A23: zinc | B23: 2009 | C23: 1149 | D23: 34 | E23: Industrias Penoles 33.9% | F23: lider/grupos conocidos + residual atomistico (aprox.) | G23: cota inferior: solo participaciones documentadas; residual tratado como atomistico
A24: zinc | B24: 2010 | C24: 773 | D24: 28 | E24: Industrias Penoles 27.8% | F24: lider/grupos conocidos + residual atomistico (aprox.) | G24: cota inferior: solo participaciones documentadas; residual tratado como atomistico
A25: zinc | B25: 2011 | C25: 635 | D25: 25 | E25: Industrias Penoles 25.2% | F25: lider/grupos conocidos + residual atomistico (aprox.) | G25: cota inferior: solo participaciones documentadas; residual tratado como atomistico
A26: zinc | B26: 2012 | C26: 566 | D26: 24 | E26: Industrias Penoles 23.8% | F26: lider/grupos conocidos + residual atomistico (aprox.) | G26: cota inferior: solo participaciones documentadas; residual tratado como atomistico
A27: zinc | B27: 2015 | C27: 1024 | D27: 32 | E27: Industrias Penoles 32.0% | F27: lider/grupos conocidos + residual atomistico (aprox.) | G27: cota inferior: solo participaciones documentadas; residual tratado como atomistico
A28: zinc | B28: 2020 | C28: 692 | D28: 26 | E28: Industrias Penoles 26.3% | F28: lider/grupos conocidos + residual atomistico (aprox.) | G28: cota inferior: solo participaciones documentadas; residual tratado como atomistico
A29: zinc | B29: 2021 | C29: 1591 | D29: 83 | E29: Newmont 28% | F29: mina->grupo vs total nacional
A30: zinc | B30: 2022 | C30: 1199 | D30: 80 | E30: Newmont 23% | F30: mina->grupo vs total nacional
A31: zinc | B31: 2023 | C31: 1551 | D31: 87 | E31: Industrias Penoles 28% | F31: mina->grupo vs total nacional
A32: zinc | B32: 2024 | C32: 1683 | D32: 81 | E32: Newmont 33% | F32: mina->grupo vs total nacional | G32: detalle por mina 2024 (CAMIMEX/SGM)
A33: plomo | B33: 2010 | C33: 524 | D33: 23 | E33: Goldcorp 22.9% | F33: lider/grupos conocidos + residual atomistico (aprox.) | G33: cota inferior: solo participaciones documentadas; residual tratado como atomistico
A34: plomo | B34: 2011 | C34: 986 | D34: 31 | E34: Goldcorp 31.4% | F34: lider/grupos conocidos + residual atomistico (aprox.) | G34: cota inferior: solo participaciones documentadas; residual tratado como atomistico
A35: plomo | B35: 2012 | C35: 858 | D35: 29 | E35: Goldcorp 29.3% | F35: lider/grupos conocidos + residual atomistico (aprox.) | G35: cota inferior: solo participaciones documentadas; residual tratado como atomistico
A36: plomo | B36: 2013 | C36: 812 | D36: 28 | E36: Goldcorp 28.5% | F36: lider/grupos conocidos + residual atomistico (aprox.) | G36: cota inferior: solo participaciones documentadas; residual tratado como atomistico
A37: plomo | B37: 2015 | C37: 961 | D37: 31 | E37: Goldcorp 31.0% | F37: lider/grupos conocidos + residual atomistico (aprox.) | G37: cota inferior: solo participaciones documentadas; residual tratado como atomistico
A38: plomo | B38: 2016 | C38: 441 | D38: 21 | E38: Goldcorp 21.0% | F38: lider/grupos conocidos + residual atomistico (aprox.) | G38: cota inferior: solo participaciones documentadas; residual tratado como atomistico
A39: plomo | B39: 2020 | C39: 973 | D39: 31 | E39: Newmont 31.2% | F39: lider/grupos conocidos + residual atomistico (aprox.) | G39: cota inferior: solo participaciones documentadas; residual tratado como atomistico
A40: plomo | B40: 2021 | C40: 1448 | D40: 80 | E40: Newmont 29% | F40: mina->grupo vs total nacional
A41: plomo | B41: 2022 | C41: 1090 | D41: 76 | E41: Newmont 25% | F41: mina->grupo vs total nacional
A42: plomo | B42: 2023 | C42: 1823 | D42: 100 | E42: Newmont 28% | F42: mina->grupo vs total nacional
...

Sheet 09 CCV
A1: CCV - Coeficiente de captura de valor (serie 1992-2025)
A2: CCV = valor_unitario_E1 / precio_refinado_USGS ; valor_unitario_E1 = valor_export_E1 / peso_export_E1. Columnas verdes: recomputo con formula de Excel y diferencia vs valor almacenado. La columna 'dif vu' marca (>0) las ~5 filas en que el valor unitario se corrigio por tonelaje minimo/atipico (silice 2016, fluorita 2018/2020, grafito 2017/2018): ahi el vu limpio != valor/peso, a proposito. 'dif CCV' debe ser ~0. Informativo en metales base (Cu~0.22, Zn~0.30); NO informativo en oro/plata (artefacto de ley). 'fuente_numerador': propio vs espejo (CIF).
A3: mineral | B3: grupo_ccv | C3: anio | D3: hs_e1 | E3: valor_export_e1_usd | F3: peso_export_e1_t | G3: valor_unitario_export_usd_t | H3: precio_refinado_usgs_usd_t | I3: ccv | J3: fuente_numerador | K3: nota | L3: valor_unitario (=formula) | M3: dif vu | N3: CCV (=formula) | O3: dif CCV
A4: barita | B4: no metalico/industrial | C4: 1992 | D4: 251110 | E4: 1244000 | F4: 19904.52 | G4: 62.5 | H4: 51.8 | I4: 1.2065 | J4: propio | L4: =IF(F4=0,"",E4/F4) | M4: =IF(ISNUMBER(L4),ROUND(L4-G4,4),"") | N4: =IF(H4=0,"",G4/H4) | O4: =IF(ISNUMBER(N4),ROUND(N4-I4,4),"")
A5: barita | B5: no metalico/industrial | C5: 1993 | D5: 251110 | E5: 4213000 | F5: 68263.624 | G5: 61.72 | H5: 45.8 | I5: 1.3475 | J5: propio | L5: =IF(F5=0,"",E5/F5) | M5: =IF(ISNUMBER(L5),ROUND(L5-G5,4),"") | N5: =IF(H5=0,"",G5/H5) | O5: =IF(ISNUMBER(N5),ROUND(N5-I5,4),"")
A6: barita | B6: no metalico/industrial | C6: 1994 | D6: 251110 | E6: 4690693 | F6: 89615.144 | G6: 52.34 | H6: 38.8 | I6: 1.349 | J6: propio | L6: =IF(F6=0,"",E6/F6) | M6: =IF(ISNUMBER(L6),ROUND(L6-G6,4),"") | N6: =IF(H6=0,"",G6/H6) | O6: =IF(ISNUMBER(N6),ROUND(N6-I6,4),"")
A7: barita | B7: no metalico/industrial | C7: 1995 | D7: 251110 | E7: 6854000 | F7: 129536.18 | G7: 52.91 | H7: 42.9 | I7: 1.2334 | J7: propio | L7: =IF(F7=0,"",E7/F7) | M7: =IF(ISNUMBER(L7),ROUND(L7-G7,4),"") | N7: =IF(H7=0,"",G7/H7) | O7: =IF(ISNUMBER(N7),ROUND(N7-I7,4),"")
A8: barita | B8: no metalico/industrial | C8: 1996 | D8: 251110 | E8: 7762014 | F8: 124343.76 | G8: 62.42 | H8: 42.7 | I8: 1.4619 | J8: propio | L8: =IF(F8=0,"",E8/F8) | M8: =IF(ISNUMBER(L8),ROUND(L8-G8,4),"") | N8: =IF(H8=0,"",G8/H8) | O8: =IF(ISNUMBER(N8),ROUND(N8-I8,4),"")
A9: barita | B9: no metalico/industrial | C9: 1997 | D9: 251110 | E9: 4439673 | F9: 65292.48 | G9: 68 | H9: 46.2 | I9: 1.4718 | J9: propio | L9: =IF(F9=0,"",E9/F9) | M9: =IF(ISNUMBER(L9),ROUND(L9-G9,4),"") | N9: =IF(H9=0,"",G9/H9) | O9: =IF(ISNUMBER(N9),ROUND(N9-I9,4),"")
A10: barita | B10: no metalico/industrial | C10: 1998 | D10: 251110 | E10: 1469473 | F10: 18144.56 | G10: 80.99 | H10: 57.1 | I10: 1.4183 | J10: propio | L10: =IF(F10=0,"",E10/F10) | M10: =IF(ISNUMBER(L10),ROUND(L10-G10,4),"") | N10: =IF(H10=0,"",G10/H10) | O10: =IF(ISNUMBER(N10),ROUND(N10-I10,4),"")
A11: barita | B11: no metalico/industrial | C11: 1999 | D11: 251110 | E11: 1030666 | F11: 15367.835 | G11: 67.07 | H11: 52.5 | I11: 1.2775 | J11: propio | L11: =IF(F11=0,"",E11/F11) | M11: =IF(ISNUMBER(L11),ROUND(L11-G11,4),"") | N11: =IF(H11=0,"",G11/H11) | O11: =IF(ISNUMBER(N11),ROUND(N11-I11,4),"")
A12: barita | B12: no metalico/industrial | C12: 2000 | D12: 251110 | E12: 767826 | F12: 8081.87 | G12: 95.01 | H12: 46.3 | I12: 2.052 | J12: propio | L12: =IF(F12=0,"",E12/F12) | M12: =IF(ISNUMBER(L12),ROUND(L12-G12,4),"") | N12: =IF(H12=0,"",G12/H12) | O12: =IF(ISNUMBER(N12),ROUND(N12-I12,4),"")
A13: barita | B13: no metalico/industrial | C13: 2001 | D13: 251110 | E13: 560838 | F13: 3698.588 | G13: 151.64 | H13: 45.4 | I13: 3.34 | J13: propio | L13: =IF(F13=0,"",E13/F13) | M13: =IF(ISNUMBER(L13),ROUND(L13-G13,4),"") | N13: =IF(H13=0,"",G13/H13) | O13: =IF(ISNUMBER(N13),ROUND(N13-I13,4),"")
A14: barita | B14: no metalico/industrial | C14: 2002 | D14: 251110 | E14: 295067 | F14: 1972.292 | G14: 149.61 | H14: 46.6 | I14: 3.2104 | J14: propio | L14: =IF(F14=0,"",E14/F14) | M14: =IF(ISNUMBER(L14),ROUND(L14-G14,4),"") | N14: =IF(H14=0,"",G14/H14) | O14: =IF(ISNUMBER(N14),ROUND(N14-I14,4),"")
A15: barita | B15: no metalico/industrial | C15: 2003 | D15: 251110 | E15: 158568 | F15: 789.517 | G15: 200.84 | H15: 45.6 | I15: 4.4044 | J15: propio | L15: =IF(F15=0,"",E15/F15) | M15: =IF(ISNUMBER(L15),ROUND(L15-G15,4),"") | N15: =IF(H15=0,"",G15/H15) | O15: =IF(ISNUMBER(N15),ROUND(N15-I15,4),"")
... A25: barita | B25: no metalico/industrial | C25: 2013 | D25: 251110 | E25: 28863901 | F25: 285870.78 | G25: 100.97 | H25: 133 | I25: 0.7592 | J25: propio | L25: =IF(F25=0,"",E25/F25) | M25: =IF(ISNUMBER(L25),ROUND(L25-G25,4),"") | N25: =IF(H25=0,"",G25/H25) | O25: =IF(ISNUMBER(N25),ROUND(N25-I25,4),"")
A26: barita | B26: no metalico/industrial | C26: 2014 | D26: 251110 | E26: 41902901 | F26: 132223.31 | G26: 316.91 | H26: 130 | I26: 2.4378 | J26: espejo | K26: numerador por ESPEJO (importaciones de socios desde Mexico; CIF, posible sesgo al alza) | L26: =IF(F26=0,"",E26/F26) | M26: =IF(ISNUMBER(L26),ROUND(L26-G26,4),"") | N26: =IF(H26=0,"",G26/H26) | O26: =IF(ISNUMBER(N26),ROUND(N26-I26,4),"")
A27: barita | B27: no metalico/industrial | C27: 2015 | D27: 251110 | E27: 1595323 | F27: 6381.292 | G27: 250 | H27: 125 | I27: 2 | J27: propio | L27: =IF(F27=0,"",E27/F27) | M27: =IF(ISNUMBER(L27),ROUND(L27-G27,4),"") | N27: =IF(H27=0,"",G27/H27) | O27: =IF(ISNUMBER(N27),ROUND(N27-I27,4),"")
A28: barita | B28: no metalico/industrial | C28: 2016 | D28: 251110 | E28: 17601565 | F28: 139552.84 | G28: 126.13 | H28: 130 | I28: 0.9702 | J28: espejo | K28: numerador por ESPEJO (importaciones de socios desde Mexico; CIF, posible sesgo al alza) | L28: =IF(F28=0,"",E28/F28) | M28: =IF(ISNUMBER(L28),ROUND(L28-G28,4),"") | N28: =IF(H28=0,"",G28/H28) | O28: =IF(ISNUMBER(N28),ROUND(N28-I28,4),"")
A29: barita | B29: no metalico/industrial | C29: 2017 | D29: 251110 | E29: 41792987 | F29: 328307.02 | G29: 127.3 | H29: 100 | I29: 1.273 | J29: espejo | K29: numerador por ESPEJO (importaciones de socios desde Mexico; CIF, posible sesgo al alza) | L29: =IF(F29=0,"",E29/F29) | M29: =IF(ISNUMBER(L29),ROUND(L29-G29,4),"") | N29: =IF(H29=0,"",G29/H29) | O29: =IF(ISNUMBER(N29),ROUND(N29-I29,4),"")
A30: barita | B30: no metalico/industrial | C30: 2018 | D30: 251110 | E30: 46377152 | F30: 339574.45 | G30: 136.57 | H30: 110 | I30: 1.2416 | J30: espejo | K30: numerador por ESPEJO (importaciones de socios desde Mexico; CIF, posible sesgo al alza) | L30: =IF(F30=0,"",E30/F30) | M30: =IF(ISNUMBER(L30),ROUND(L30-G30,4),"") | N30: =IF(H30=0,"",G30/H30) | O30: =IF(ISNUMBER(N30),ROUND(N30-I30,4),"")
A31: barita | B31: no metalico/industrial | C31: 2019 | D31: 251110 | E31: 49841739 | F31: 378413.32 | G31: 131.71 | H31: 113 | I31: 1.1656 | J31: espejo | K31: numerador por ESPEJO (importaciones de socios desde Mexico; CIF, posible sesgo al alza) | L31: =IF(F31=0,"",E31/F31) | M31: =IF(ISNUMBER(L31),ROUND(L31-G31,4),"") | N31: =IF(H31=0,"",G31/H31) | O31: =IF(ISNUMBER(N31),ROUND(N31-I31,4),"")
A32: barita | B32: no metalico/industrial | C32: 2020 | D32: 251110 | E32: 34531482 | F32: 249004.05 | G32: 138.68 | H32: 115.53 | I32: 1.2004 | J32: espejo | K32: numerador por ESPEJO (importaciones de socios desde Mexico; CIF, posible sesgo al alza) | L32: =IF(F32=0,"",E32/F32) | M32: =IF(ISNUMBER(L32),ROUND(L32-G32,4),"") | N32: =IF(H32=0,"",G32/H32) | O32: =IF(ISNUMBER(N32),ROUND(N32-I32,4),"")
A33: barita | B33: no metalico/industrial | C33: 2021 | D33: 251110 | E33: 19124233 | F33: 183157.85 | G33: 104.41 | H33: 105.42 | I33: 0.9904 | J33: propio | L33: =IF(F33=0,"",E33/F33) | M33: =IF(ISNUMBER(L33),ROUND(L33-G33,4),"") | N33: =IF(H33=0,"",G33/H33) | O33: =IF(ISNUMBER(N33),ROUND(N33-I33,4),"")
A34: barita | B34: no metalico/industrial | C34: 2022 | D34: 251110 | E34: 27236605 | F34: 231514.31 | G34: 117.65 | H34: 91.54 | I34: 1.2852 | J34: propio | L34: =IF(F34=0,"",E34/F34) | M34: =IF(ISNUMBER(L34),ROUND(L34-G34,4),"") | N34: =IF(H34=0,"",G34/H34) | O34: =IF(ISNUMBER(N34),ROUND(N34-I34,4),"")
A35: barita | B35: no metalico/industrial | C35: 2023 | D35: 251110 | E35: 26073174 | F35: 217538.9 | G35: 119.86 | H35: 137.62 | I35: 0.8709 | J35: propio | L35: =IF(F35=0,"",E35/F35) | M35: =IF(ISNUMBER(L35),ROUND(L35-G35,4),"") | N35: =IF(H35=0,"",G35/H35) | O35: =IF(ISNUMBER(N35),ROUND(N35-I35,4),"")
A36: barita | B36: no metalico/industrial | C36: 2024 | D36: 251110 | E36: 13093040 | F36: 106562.4 | G36: 122.87 | H36: 132.57 | I36: 0.9268 | J36: propio | L36: =IF(F36=0,"",E36/F36) | M36: =IF(ISNUMBER(L36),ROUND(L36-G36,4),"") | N36: =IF(H36=0,"",G36/H36) | O36: =IF(ISNUMBER(N36),ROUND(N36-I36,4),"")
A37: barita | B37: no metalico/industrial | C37: 2025 | D37: 251110 | E37: 27730976 | F37: 255119.24 | G37: 108.7 | H37: 132.57 | I37: 0.8199 | J37: propio | L37: =IF(F37=0,"",E37/F37) | M37: =IF(ISNUMBER(L37),ROUND(L37-G37,4),"") | N37: =IF(H37=0,"",G37/H37) | O37: =IF(ISNUMBER(N37),ROUND(N37-I37,4),"")
A38: cobre | B38: metal base | C38: 1992 | D38: 2603 | E38: 31605000 | F38: 67482.216 | G38: 468.35 | H38: 2370 | I38: 0.1976 | J38: propio | L38: =IF(F38=0,"",E38/F38) | M38: =IF(ISNUMBER(L38),ROUND(L38-G38,4),"") | N38: =IF(H38=0,"",G38/H38) | O38: =IF(ISNUMBER(N38),ROUND(N38-I38,4),"")
A39: cobre | B39: metal base | C39: 1993 | D39: 2603 | E39: 61000 | F39: 82.925 | G39: 735.6 | H39: 2020 | I39: 0.3642 | J39: propio | L39: =IF(F39=0,"",E39/F39) | M39: =IF(ISNUMBER(L39),ROUND(L39-G39,4),"") | N39: =IF(H39=0,"",G39/H39) | O39: =IF(ISNUMBER(N39),ROUND(N39-I39,4),"")
A40: cobre | B40: metal base | C40: 1994 | D40: 2603 | E40: 4748557 | F40: 8304.535 | G40: 571.8 | H40: 2450 | I40: 0.2334 | J40: propio | L40: =IF(F40=0,"",E40/F40) | M40: =IF(ISNUMBER(L40),ROUND(L40-G40,4),"") | N40: =IF(H40=0,"",G40/H40) | O40: =IF(ISNUMBER(N40),ROUND(N40-I40,4),"")
A41: cobre | B41: metal base | C41: 1995 | D41: 2603 | E41: 20182000 | F41: 31652.52 | G41: 637.61 | H41: 3050 | I41: 0.2091 | J41: propio | L41: =IF(F41=0,"",E41/F41) | M41: =IF(ISNUMBER(L41),ROUND(L41-G41,4),"") | N41: =IF(H41=0,"",G41/H41) | O41: =IF(ISNUMBER(N41),ROUND(N41-I41,4),"")
A42: cobre | B42: metal base | C42: 1996 | D42: 2603 | E42: 15994984 | F42: 53179.452 | G42: 300.77 | H42: 2400 | I42: 0.1253 | J42: propio | L42: =IF(F42=0,"",E42/F42) | M42: =IF(ISNUMBER(L42),ROUND(L42-G42,4),"") | N42: =IF(H42=0,"",G42/H42) | O42: =IF(ISNUMBER(N42),ROUND(N42-I42,4),"")
A43: cobre | B43: metal base | C43: 1997 | D43: 2603 | E43: 18588480 | F43: 44533.856 | G43: 417.4 | H43: 2360 | I43: 0.1769 | J43: propio | L43: =IF(F43=0,"",E43/F43) | M43: =IF(ISNUMBER(L43),ROUND(L43-G43,4),"") | N43: =IF(H43=0,"",G43/H43) | O43: =IF(ISNUMBER(N43),ROUND(N43-I43,4),"")
A44: cobre | B44: metal base | C44: 1998 | D44: 2603 | E44: 25456432 | F44: 68722.216 | G44: 370.43 | H44: 1730 | I44: 0.2141 | J44: propio | L44: =IF(F44=0,"",E44/F44) | M44: =IF(ISNUMBER(L44),ROUND(L44-G44,4),"") | N44: =IF(H44=0,"",G44/H44) | O44: =IF(ISNUMBER(N44),ROUND(N44-I44,4),"")
... A60: cobre | B60: metal base | C60: 2014 | D60: 2603 | E60: 1170641398 | F60: 659351.02 | G60: 1775.44 | H60: 7010 | I60: 0.2533 | J60: propio | L60: =IF(F60=0,"",E60/F60) | M60: =IF(ISNUMBER(L60),ROUND(L60-G60,4),"") | N60: =IF(H60=0,"",G60/H60) | O60: =IF(ISNUMBER(N60),ROUND(N60-I60,4),"")
A61: cobre | B61: metal base | C61: 2015 | D61: 2603 | E61: 2.3460378e+09 | F61: 1467244.6 | G61: 1598.94 | H61: 5650 | I61: 0.283 | J61: espejo | K61: numerador por ESPEJO (importaciones de socios desde Mexico; CIF, posible sesgo al alza) | L61: =IF(F61=0,"",E61/F61) | M61: =IF(ISNUMBER(L61),ROUND(L61-G61,4),"") | N61: =IF(H61=0,"",G61/H61) | O61: =IF(ISNUMBER(N61),ROUND(N61-I61,4),"")
A62: cobre | B62: metal base | C62: 2016 | D62: 2603 | E62: 1323559500 | F62: 1097421.1 | G62: 1206.06 | H62: 4960 | I62: 0.2432 | J62: propio | L62: =IF(F62=0,"",E62/F62) | M62: =IF(ISNUMBER(L62),ROUND(L62-G62,4),"") | N62: =IF(H62=0,"",G62/H62) | O62: =IF(ISNUMBER(N62),ROUND(N62-I62,4),"")
A63: cobre | B63: metal base | C63: 2017 | D63: 2603 | E63: 1568943333 | F63: 1218662.5 | G63: 1287.43 | H63: 6290 | I63: 0.2047 | J63: propio | L63: =IF(F63=0,"",E63/F63) | M63: =IF(ISNUMBER(L63),ROUND(L63-G63,4),"") | N63: =IF(H63=0,"",G63/H63) | O63: =IF(ISNUMBER(N63),ROUND(N63-I63,4),"")
A64: cobre | B64: metal base | C64: 2018 | D64: 2603 | E64: 2318095785 | F64: 1583502.4 | G64: 1463.9 | H64: 6590 | I64: 0.2221 | J64: propio | L64: =IF(F64=0,"",E64/F64) | M64: =IF(ISNUMBER(L64),ROUND(L64-G64,4),"") | N64: =IF(H64=0,"",G64/H64) | O64: =IF(ISNUMBER(N64),ROUND(N64-I64,4),"")
...

Sheet 10 Precios
A1: Precios USGS anuales empalmados (denominador del CCV y valuacion de produccion)
A2: Precio de referencia del producto refinado, USD/t nominal y constante 1998. 'metodo'/'serie_fuente'/'factor' documentan el empalme entre ediciones del USGS. Resultado de la extraccion USGS (no aritmetico simple: enlace por factor).
A3: mineral | B3: anio | C3: precio_usd_t_nominal | D3: precio_usd_t_const1998 | E3: metodo | F3: serie_fuente | G3: factor
A4: Barita | B4: 1990 | C4: 46.7 | D4: 58.2 | E4: DS-140 | F4: USGS DS-140 valor unitario consumo aparente
A5: Barita | B5: 1991 | C5: 51.6 | D5: 61.8 | E5: DS-140 | F5: USGS DS-140 valor unitario consumo aparente
A6: Barita | B6: 1992 | C6: 51.8 | D6: 60.1 | E6: DS-140 | F6: USGS DS-140 valor unitario consumo aparente
A7: Barita | B7: 1993 | C7: 45.8 | D7: 51.6 | E7: DS-140 | F7: USGS DS-140 valor unitario consumo aparente
A8: Barita | B8: 1994 | C8: 38.8 | D8: 42.7 | E8: DS-140 | F8: USGS DS-140 valor unitario consumo aparente
A9: Barita | B9: 1995 | C9: 42.9 | D9: 45.9 | E9: DS-140 | F9: USGS DS-140 valor unitario consumo aparente
A10: Barita | B10: 1996 | C10: 42.7 | D10: 44.4 | E10: DS-140 | F10: USGS DS-140 valor unitario consumo aparente
A11: Barita | B11: 1997 | C11: 46.2 | D11: 46.9 | E11: DS-140 | F11: USGS DS-140 valor unitario consumo aparente
A12: Barita | B12: 1998 | C12: 57.1 | D12: 57.1 | E12: DS-140 | F12: USGS DS-140 valor unitario consumo aparente
A13: Barita | B13: 1999 | C13: 52.5 | D13: 51.4 | E13: DS-140 | F13: USGS DS-140 valor unitario consumo aparente
A14: Barita | B14: 2000 | C14: 46.3 | D14: 43.8 | E14: DS-140 | F14: USGS DS-140 valor unitario consumo aparente
A15: Barita | B15: 2001 | C15: 45.4 | D15: 41.8 | E15: DS-140 | F15: USGS DS-140 valor unitario consumo aparente
... A310: Zinc | B310: 2022 | C310: 4190 | D310: 2330 | E310: DS-140 | F310: USGS DS-140 valor unitario consumo aparente
A311: Oro | B311: 2023 | C311: 62454119 | D311: 33409762 | E311: empalme | F311: Cochilco London Fix AM anual (enc. 2022) | G311: 32139.229
A312: Oro | B312: 2024 | C312: 76727948 | D312: 39869602 | E312: empalme | F312: Cochilco London Fix AM anual (enc. 2022) | G312: 32139.229
A313: Oro | B313: 2025 | C313: 1.0605946e+08 | D313: 53605245 | E313: empalme | F313: MCS 2026 Engelhard 2025e (enc. 2022) | G313: 32139.229
A314: Plata | B314: 2022 | C314: 701028.12 | D314: 390451.5 | E314: empalme | F314: Cochilco London Fix anual (enc. 2021) | G314: 32226.924
A315: Plata | B315: 2023 | C315: 753678.95 | D315: 403179.73 | E315: empalme | F315: Cochilco London Fix anual (enc. 2021) | G315: 32226.924
A316: Plata | B316: 2024 | C316: 910220.06 | D316: 472971.22 | E316: empalme | F316: Cochilco London Fix anual (enc. 2021) | G316: 32226.924
A317: Plata | B317: 2025 | C317: 1224623.1 | D317: 618956.8 | E317: empalme | F317: MCS 2026 precio bullion 2025e (enc. 2021) | G317: 32226.924
A318: Cobre | B318: 2021 | C318: 9543.3688 | D318: 5740.7429 | E318: empalme | F318: Cochilco BML anual (enc. 2020) | G318: 22.587347
A319: Cobre | B319: 2022 | C319: 9030.9842 | D319: 5029.9856 | E319: empalme | F319: Cochilco BML anual (enc. 2020) | G319: 22.587347
A320: Cobre | B320: 2023 | C320: 8693.0568 | D320: 4650.3412 | E320: empalme | F320: Cochilco BML anual (enc. 2020) | G320: 22.587347
A321: Cobre | B321: 2024 | C321: 9368.5333 | D321: 4868.1048 | E321: empalme | F321: Cochilco BML anual (enc. 2020) | G321: 22.587347
A322: Cobre | B322: 2025 | C322: 9938.4328 | D322: 5023.1459 | E322: empalme | F322: MCS 2026 LME cash 2025e (enc. 2020) | G322: 22.587347
... A363: Fluorita | B363: 2025 | C363: 439.67742 | D363: 222.22456 | E363: empalme | F363: MCS valor unitario imports grado acido CIF (enc. 2006) | G363: 0.93548387

Sheet 11 Peso bloque prod
A1: Peso del bloque - valor de produccion (1992-2022)
A2: valor_prod = vol_t x precio_usd_t. share_bloque = valor_prod / (suma del bloque ese anio) x 100. Columnas verdes recomputan ambas con formula de Excel (SUMIFS por anio) y su diferencia vs script. Nota: 'precio_usd_t' se muestra redondeado a 1 decimal, por lo que 'dif valor' puede mostrar diferencias <0.02% (redondeo de despliegue, no error); el share cuadra exacto.
A3: anio | B3: mineral | C3: vol_t | D3: precio_usd_t | E3: valor_prod_usd | F3: share_bloque_pct | G3: anio_completo | H3: valor_prod (=formula) | I3: dif valor | J3: share_bloque (=formula) % | K3: dif share
A4: 1992 | B4: barita | C4: 188000 | D4: 51.8 | E4: 9738400 | F4: 0.56 | G4: si | H4: =C4*D4 | I4: =ROUND(H4-E4,0) | J4: =ROUND(E4/SUMIFS($E$4:$E$313,$A$4:$A$313,A4)*100,2) | K4: =ROUND(J4-F4,2)
A5: 1993 | B5: barita | C5: 136000 | D5: 45.8 | E5: 6228800 | F5: 0.38 | G5: si | H5: =C5*D5 | I5: =ROUND(H5-E5,0) | J5: =ROUND(E5/SUMIFS($E$4:$E$313,$A$4:$A$313,A5)*100,2) | K5: =ROUND(J5-F5,2)
A6: 1994 | B6: barita | C6: 86605 | D6: 38.8 | E6: 3360274 | F6: 0.17 | G6: si | H6: =C6*D6 | I6: =ROUND(H6-E6,0) | J6: =ROUND(E6/SUMIFS($E$4:$E$313,$A$4:$A$313,A6)*100,2) | K6: =ROUND(J6-F6,2)
A7: 1995 | B7: barita | C7: 248367 | D7: 42.9 | E7: 10654944 | F7: 0.43 | G7: si | H7: =C7*D7 | I7: =ROUND(H7-E7,0) | J7: =ROUND(E7/SUMIFS($E$4:$E$313,$A$4:$A$313,A7)*100,2) | K7: =ROUND(J7-F7,2)
A8: 1996 | B8: barita | C8: 470028 | D8: 42.7 | E8: 20070196 | F8: 0.83 | G8: si | H8: =C8*D8 | I8: =ROUND(H8-E8,0) | J8: =ROUND(E8/SUMIFS($E$4:$E$313,$A$4:$A$313,A8)*100,2) | K8: =ROUND(J8-F8,2)
A9: 1997 | B9: barita | C9: 236606 | D9: 46.2 | E9: 10931197 | F9: 0.42 | G9: si | H9: =C9*D9 | I9: =ROUND(H9-E9,0) | J9: =ROUND(E9/SUMIFS($E$4:$E$313,$A$4:$A$313,A9)*100,2) | K9: =ROUND(J9-F9,2)
A10: 1998 | B10: barita | C10: 161555 | D10: 57.1 | E10: 9224790 | F10: 0.41 | G10: si | H10: =C10*D10 | I10: =ROUND(H10-E10,0) | J10: =ROUND(E10/SUMIFS($E$4:$E$313,$A$4:$A$313,A10)*100,2) | K10: =ROUND(J10-F10,2)
A11: 1999 | B11: barita | C11: 157953 | D11: 52.5 | E11: 8292532 | F11: 0.41 | G11: si | H11: =C11*D11 | I11: =ROUND(H11-E11,0) | J11: =ROUND(E11/SUMIFS($E$4:$E$313,$A$4:$A$313,A11)*100,2) | K11: =ROUND(J11-F11,2)
A12: 2000 | B12: barita | C12: 127420 | D12: 46.3 | E12: 5899546 | F12: 0.27 | G12: si | H12: =C12*D12 | I12: =ROUND(H12-E12,0) | J12: =ROUND(E12/SUMIFS($E$4:$E$313,$A$4:$A$313,A12)*100,2) | K12: =ROUND(J12-F12,2)
A13: 2001 | B13: barita | C13: 142017 | D13: 45.4 | E13: 6447572 | F13: 0.33 | G13: si | H13: =C13*D13 | I13: =ROUND(H13-E13,0) | J13: =ROUND(E13/SUMIFS($E$4:$E$313,$A$4:$A$313,A13)*100,2) | K13: =ROUND(J13-F13,2)
A14: 2002 | B14: barita | C14: 163620 | D14: 46.6 | E14: 7624692 | F14: 0.41 | G14: si | H14: =C14*D14 | I14: =ROUND(H14-E14,0) | J14: =ROUND(E14/SUMIFS($E$4:$E$313,$A$4:$A$313,A14)*100,2) | K14: =ROUND(J14-F14,2)
A15: 2003 | B15: barita | C15: 287451 | D15: 45.6 | E15: 13107766 | F15: 0.64 | G15: si | H15: =C15*D15 | I15: =ROUND(H15-E15,0) | J15: =ROUND(E15/SUMIFS($E$4:$E$313,$A$4:$A$313,A15)*100,2) | K15: =ROUND(J15-F15,2)
... A313: 2022 | B313: zinc | C313: 744341 | D313: 4190 | E313: 3118788790 | F313: 13.65 | G313: si | H313: =C313*D313 | I313: =ROUND(H313-E313,0) | J313: =ROUND(E313/SUMIFS($E$4:$E$313,$A$4:$A$313,A313)*100,2) | K313: =ROUND(J313-F313,2)

Sheet 12 Peso bloque X
A1: Peso del bloque - exportaciones (1992-2024)
A2: share_bloque = X_bloque / X_nacional x 100. Columna verde recomputa con formula de Excel y su diferencia. X_bloque de Comtrade; X_nacional del Banco Mundial (TX.VAL.MRCH.CD.WT, coincide con INEGI).
A3: anio | B3: X_bloque_musd | C3: X_nacional_musd | D3: share_bloque_pct | E3: share (=formula) % | F3: dif
A4: 1992 | B4: 1139.7 | C4: 46196 | D4: 2.467 | E4: =ROUND(B4/C4*100,2) | F4: =ROUND(E4-D4,2)
A5: 1993 | B5: 1214.1 | C5: 51886 | D5: 2.34 | E5: =ROUND(B5/C5*100,2) | F5: =ROUND(E5-D5,2)
A6: 1994 | B6: 1290.4 | C6: 60882 | D6: 2.12 | E6: =ROUND(B6/C6*100,2) | F6: =ROUND(E6-D6,2)
A7: 1995 | B7: 1894.5 | C7: 79542 | D7: 2.382 | E7: =ROUND(B7/C7*100,2) | F7: =ROUND(E7-D7,2)
A8: 1996 | B8: 1906.9 | C8: 96000 | D8: 1.986 | E8: =ROUND(B8/C8*100,2) | F8: =ROUND(E8-D8,2)
A9: 1997 | B9: 2057.5 | C9: 110431 | D9: 1.863 | E9: =ROUND(B9/C9*100,2) | F9: =ROUND(E9-D9,2)
A10: 1998 | B10: 2062.5 | C10: 117460 | D10: 1.756 | E10: =ROUND(B10/C10*100,2) | F10: =ROUND(E10-D10,2)
A11: 1999 | B11: 1964.2 | C11: 136391 | D11: 1.44 | E11: =ROUND(B11/C11*100,2) | F11: =ROUND(E11-D11,2)
A12: 2000 | B12: 2189.1 | C12: 166367 | D12: 1.316 | E12: =ROUND(B12/C12*100,2) | F12: =ROUND(E12-D12,2)
A13: 2001 | B13: 1926.9 | C13: 158547 | D13: 1.215 | E13: =ROUND(B13/C13*100,2) | F13: =ROUND(E13-D13,2)
A14: 2002 | B14: 1892.2 | C14: 160682 | D14: 1.178 | E14: =ROUND(B14/C14*100,2) | F14: =ROUND(E14-D14,2)
A15: 2003 | B15: 1995.5 | C15: 165396 | D15: 1.206 | E15: =ROUND(B15/C15*100,2) | F15: =ROUND(E15-D15,2)
... A36: 2024 | B36: 13725.7 | C36: 617677 | D36: 2.222 | E36: =ROUND(B36/C36*100,2) | F36: =ROUND(E36-D36,2)

Sheet 13 Peso bloque PIB
A1: Peso del bloque - PIB, VBP y empleo (MIP 2013 / 2018)
A2: Filas 'mineral' = cada mineral; 'BLOQUE_10' = suma; 'referencia' = TOTAL_economia / mineria_212 / mineria_21. pct_pib_economia = pib_mmp / PIB_total x 100 (columna verde recomputa contra la fila de referencia del mismo anio).
A3: anio | B3: nivel | C3: codigo | D3: mineral | E3: pib_mmp | F3: vbp_mmp | G3: pt_empleos | H3: remun_mmp | I3: pct_pib_economia | J3: pct_pib_mineria212 | K3: pct_vbp_economia | L3: pct_vbp_mineria212 | M3: pct_empleo_economia | N3: pct_empleo_mineria212 | O3: pct_pib_economia (=formula) | P3: dif
A4: 2013 | B4: mineral | C4: 212393 | D4: barita | E4: 222.8 | F4: 368.3 | G4: 1003 | H4: 125.1 | I4: 0.0014 | J4: 0.132 | K4: 0.0013 | L4: 0.139 | M4: 0.0017 | N4: 0.403 | O4: =IFERROR(ROUND(E4/SUMIFS($E$4:$E$29,$A$4:$A$29,A4,$D$4:$D$29,"TOTAL_economia")*100,4),"") | P4: =IF(ISNUMBER(O4),ROUND(O4-I4,4),"")
A5: 2013 | B5: mineral | C5: 212231 | D5: cobre | E5: 28083.9 | F5: 39971.4 | G5: 12523 | H5: 1105.6 | I5: 0.1794 | J5: 16.697 | K5: 0.1446 | L5: 15.135 | M5: 0.0218 | N5: 5.031 | O5: =IFERROR(ROUND(E5/SUMIFS($E$4:$E$29,$A$4:$A$29,A5,$D$4:$D$29,"TOTAL_economia")*100,4),"") | P5: =IF(ISNUMBER(O5),ROUND(O5-I5,4),"")
A6: 2013 | B6: mineral | C6: 212395 | D6: fluorita | E6: 1562.8 | F6: 2218.2 | G6: 1713 | H6: 208.2 | I6: 0.01 | J6: 0.929 | K6: 0.008 | L6: 0.84 | M6: 0.003 | N6: 0.688 | O6: =IFERROR(ROUND(E6/SUMIFS($E$4:$E$29,$A$4:$A$29,A6,$D$4:$D$29,"TOTAL_economia")*100,4),"") | P6: =IF(ISNUMBER(O6),ROUND(O6-I6,4),"")
A7: 2013 | B7: mineral | C7: 212396 | D7: grafito | E7: 123.7 | F7: 164.1 | G7: 229 | H7: 31 | I7: 0.0008 | J7: 0.074 | K7: 0.0006 | L7: 0.062 | M7: 0.0004 | N7: 0.092 | O7: =IFERROR(ROUND(E7/SUMIFS($E$4:$E$29,$A$4:$A$29,A7,$D$4:$D$29,"TOTAL_economia")*100,4),"") | P7: =IF(ISNUMBER(O7),ROUND(O7-I7,4),"")
A8: 2013 | B8: mineral | C8: 212291 | D8: manganeso | E8: 373.9 | F8: 486 | G8: 672 | H8: 107.5 | I8: 0.0024 | J8: 0.222 | K8: 0.0018 | L8: 0.184 | M8: 0.0012 | N8: 0.27 | O8: =IFERROR(ROUND(E8/SUMIFS($E$4:$E$29,$A$4:$A$29,A8,$D$4:$D$29,"TOTAL_economia")*100,4),"") | P8: =IF(ISNUMBER(O8),ROUND(O8-I8,4),"")
A9: 2013 | B9: mineral | C9: 212221 | D9: oro | E9: 32499 | F9: 49607.2 | G9: 12310 | H9: 169.2 | I9: 0.2076 | J9: 19.321 | K9: 0.1795 | L9: 18.783 | M9: 0.0214 | N9: 4.946 | O9: =IFERROR(ROUND(E9/SUMIFS($E$4:$E$29,$A$4:$A$29,A9,$D$4:$D$29,"TOTAL_economia")*100,4),"") | P9: =IF(ISNUMBER(O9),ROUND(O9-I9,4),"")
A10: 2013 | B10: mineral | C10: 212222 | D10: plata | E10: 29754.2 | F10: 44680.4 | G10: 17983 | H10: 1614.3 | I10: 0.1901 | J10: 17.69 | K10: 0.1616 | L10: 16.918 | M10: 0.0313 | N10: 7.225 | O10: =IFERROR(ROUND(E10/SUMIFS($E$4:$E$29,$A$4:$A$29,A10,$D$4:$D$29,"TOTAL_economia")*100,4),"") | P10: =IF(ISNUMBER(O10),ROUND(O10-I10,4),"")
A11: 2013 | B11: mineral | C11: 212232 | D11: plomo-zinc | E11: 13865.2 | F11: 20045.8 | G11: 10178 | H11: 1509.7 | I11: 0.0886 | J11: 8.243 | K11: 0.0725 | L11: 7.59 | M11: 0.0177 | N11: 4.089 | O11: =IFERROR(ROUND(E11/SUMIFS($E$4:$E$29,$A$4:$A$29,A11,$D$4:$D$29,"TOTAL_economia")*100,4),"") | P11: =IF(ISNUMBER(O11),ROUND(O11-I11,4),"")
A12: 2013 | B12: mineral | C12: 212324 | D12: silice | E12: 3154.1 | F12: 4898.3 | G12: 2863 | H12: 391 | I12: 0.0202 | J12: 1.875 | K12: 0.0177 | L12: 1.855 | M12: 0.005 | N12: 1.15 | O12: =IFERROR(ROUND(E12/SUMIFS($E$4:$E$29,$A$4:$A$29,A12,$D$4:$D$29,"TOTAL_economia")*100,4),"") | P12: =IF(ISNUMBER(O12),ROUND(O12-I12,4),"")
A13: 2013 | B13: BLOQUE_10 | D13: bloque 10 minerales | E13: 109639.6 | F13: 162439.8 | G13: 59474 | H13: 5261.6 | I13: 0.7005 | J13: 65.183 | K13: 0.5876 | L13: 61.506 | M13: 0.1035 | N13: 23.894 | O13: =IFERROR(ROUND(E13/SUMIFS($E$4:$E$29,$A$4:$A$29,A13,$D$4:$D$29,"TOTAL_economia")*100,4),"") | P13: =IF(ISNUMBER(O13),ROUND(O13-I13,4),"")
A14: 2013 | B14: referencia | D14: TOTAL_economia | E14: 15652079 | F14: 27642648 | G14: 57465990 | I14: 100 | K14: 100 | M14: 100 | O14: =IFERROR(ROUND(E14/SUMIFS($E$4:$E$29,$A$4:$A$29,A14,$D$4:$D$29,"TOTAL_economia")*100,4),"") | P14: =IF(ISNUMBER(O14),ROUND(O14-I14,4),"")
A15: 2013 | B15: referencia | D15: mineria_212 | E15: 168202.3 | F15: 264101.8 | G15: 248908 | I15: 1.075 | K15: 0.955 | M15: 0.433 | O15: =IFERROR(ROUND(E15/SUMIFS($E$4:$E$29,$A$4:$A$29,A15,$D$4:$D$29,"TOTAL_economia")*100,4),"") | P15: =IF(ISNUMBER(O15),ROUND(O15-I15,4),"")
A16: 2013 | B16: referencia | D16: mineria_21 | E16: 1147243.6 | F16: 1463213.4 | G16: 0 | I16: 7.33 | K16: 5.293 | M16: 0 | O16: =IFERROR(ROUND(E16/SUMIFS($E$4:$E$29,$A$4:$A$29,A16,$D$4:$D$29,"TOTAL_economia")*100,4),"") | P16: =IF(ISNUMBER(O16),ROUND(O16-I16,4),"")
A17: 2018 | B17: mineral | C17: 212393 | D17: barita | E17: 452.4 | F17: 685.6 | G17: 1713 | H17: 228.5 | I17: 0.002 | J17: 0.169 | K17: 0.0016 | L17: 0.163 | M17: 0.0029 | N17: 0.864 | O17: =IFERROR(ROUND(E17/SUMIFS($E$4:$E$29,$A$4:$A$29,A17,$D$4:$D$29,"TOTAL_economia")*100,4),"") | P17: =IF(ISNUMBER(O17),ROUND(O17-I17,4),"")
A18: 2018 | B18: mineral | C18: 212231 | D18: cobre | E18: 62412.4 | F18: 92893 | G18: 8718 | H18: 3230.4 | I18: 0.2692 | J18: 23.257 | K18: 0.2214 | L18: 22.101 | M18: 0.0147 | N18: 4.397 | O18: =IFERROR(ROUND(E18/SUMIFS($E$4:$E$29,$A$4:$A$29,A18,$D$4:$D$29,"TOTAL_economia")*100,4),"") | P18: =IF(ISNUMBER(O18),ROUND(O18-I18,4),"")
A19: 2018 | B19: mineral | C19: 212395 | D19: fluorita | E19: 3717.5 | F19: 5861.8 | G19: 740 | H19: 78.5 | I19: 0.016 | J19: 1.385 | K19: 0.014 | L19: 1.395 | M19: 0.0012 | N19: 0.373 | O19: =IFERROR(ROUND(E19/SUMIFS($E$4:$E$29,$A$4:$A$29,A19,$D$4:$D$29,"TOTAL_economia")*100,4),"") | P19: =IF(ISNUMBER(O19),ROUND(O19-I19,4),"")
A20: 2018 | B20: mineral | C20: 212396 | D20: grafito | E20: 568.1 | F20: 719.8 | G20: 627 | H20: 112 | I20: 0.0025 | J20: 0.212 | K20: 0.0017 | L20: 0.171 | M20: 0.0011 | N20: 0.316 | O20: =IFERROR(ROUND(E20/SUMIFS($E$4:$E$29,$A$4:$A$29,A20,$D$4:$D$29,"TOTAL_economia")*100,4),"") | P20: =IF(ISNUMBER(O20),ROUND(O20-I20,4),"")
A21: 2018 | B21: mineral | C21: 212291 | D21: manganeso | E21: 309.3 | F21: 635 | G21: 523 | H21: 204.2 | I21: 0.0013 | J21: 0.115 | K21: 0.0015 | L21: 0.151 | M21: 0.0009 | N21: 0.264 | O21: =IFERROR(ROUND(E21/SUMIFS($E$4:$E$29,$A$4:$A$29,A21,$D$4:$D$29,"TOTAL_economia")*100,4),"") | P21: =IF(ISNUMBER(O21),ROUND(O21-I21,4),"")
